Workbook

Sheet Data_set 
A1: Menu Category | B1: Menu Items | C1: Sodium Z-Score | D1: Per Serve Size | E1: Energy (kCal) | F1: Protein (g) | G1: Protein-to-Weight Ratio | H1: Total fat (g) | I1: Sat Fat (g) | J1: Trans fat (g) | K1: Cholesterols (mg) | L1: Total carbohydrate (g) | M1: Total Sugars (g) | N1: Added Sugars (g) | O1: Sodium (mg) | P1: Nutrient-Density Index (NDI | Q1: Strategic Health Tier
A2: Regular Menu | B2: Ghee Rice with Mc Spicy Fried Chicken 1 pc | C2: =(O2-$K$147)/($K$150) -> 4.3059932 | D2: 325 | E2: 720.3 | F2: 26.91 | G2: =Table2[[#This Row],[Protein (g)]]/Table2[[#This Row],[Per Serve Size]] -> 0.0828 | H2: 29.2 | I2: 5.08 | J2: 0.3 | K2: 31.32 | L2: 77.47 | M2: 3.28 | N2: 0.35 | O2: 2399.49 | P2: =(Table2[[#This Row],[Protein (g)]]/Table2[[#This Row],[Energy (kCal)]])*100-(Table2[[#This Row],[Sodium (mg)]]/1000) -> 1.3364534 | Q2: =IF(P2 > 5, "Premium Health", IF(P2 > 3, "Balanced", "High-Risk")) -> High-Risk
A3: Gourmet Menu | B3: Chunky Chipotle American Burger Chicken | C3: =(O3-$K$147)/($K$150) -> 3.2635985 | D3: 301 | E3: 641.36 | F3: 39.47 | G3: =Table2[[#This Row],[Protein (g)]]/Table2[[#This Row],[Per Serve Size]] -> 0.13112957 | H3: 31.51 | I3: 9.54 | J3: 0.26 | K3: 110.37 | L3: 46.24 | M3: 9.16 | N3: 6.32 | O3: 1906.27 | P3: =(Table2[[#This Row],[Protein (g)]]/Table2[[#This Row],[Energy (kCal)]])*100-(Table2[[#This Row],[Sodium (mg)]]/1000) -> 4.24784 | Q3: =IF(P3 > 5, "Premium Health", IF(P3 > 3, "Balanced", "High-Risk")) -> Balanced
A4: Regular Menu | B4: Chicken Maharaja Mac | C4: =(O4-$K$147)/($K$150) -> 3.1546291 | D4: 296 | E4: 689.12 | F4: 34 | G4: =Table2[[#This Row],[Protein (g)]]/Table2[[#This Row],[Per Serve Size]] -> 0.11486486 | H4: 36.69 | I4: 10.33 | J4: 0.25 | K4: 81.49 | L4: 55.39 | M4: 8.92 | N4: 6.14 | O4: 1854.71 | P4: =(Table2[[#This Row],[Protein (g)]]/Table2[[#This Row],[Energy (kCal)]])*100-(Table2[[#This Row],[Sodium (mg)]]/1000) -> 3.0791187 | Q4: =IF(P4 > 5, "Premium Health", IF(P4 > 3, "Balanced", "High-Risk")) -> Balanced
A5: Gourmet Menu | B5: Chicken Cheese Lava Burger | C5: =(O5-$K$147)/($K$150) -> 2.9228473 | D5: 307 | E5: 834.36 | F5: 27.37 | G5: =Table2[[#This Row],[Protein (g)]]/Table2[[#This Row],[Per Serve Size]] -> 0.089153094 | H5: 45.18 | I5: 17 | J5: 0.27 | K5: 73.11 | L5: 76.03 | M5: 16.75 | N5: 10.01 | O5: 1745.04 | P5: =(Table2[[#This Row],[Protein (g)]]/Table2[[#This Row],[Energy (kCal)]])*100-(Table2[[#This Row],[Sodium (mg)]]/1000) -> 1.5353186 | Q5: =IF(P5 > 5, "Premium Health", IF(P5 > 3, "Balanced", "High-Risk")) -> High-Risk
A6: Gourmet Menu | B6: McSpicy Premium Chicken Burger | C6: =(O6-$K$147)/($K$150) -> 2.6477609 | D6: 264.5 | E6: 622.25 | F6: 31.49 | G6: =Table2[[#This Row],[Protein (g)]]/Table2[[#This Row],[Per Serve Size]] -> 0.11905482 | H6: 34.65 | I6: 15.55 | J6: 0.24 | K6: 302.61 | L6: 43.6 | M6: 6.07 | N6: 2.64 | O6: 1614.88 | P6: =(Table2[[#This Row],[Protein (g)]]/Table2[[#This Row],[Energy (kCal)]])*100-(Table2[[#This Row],[Sodium (mg)]]/1000) -> 3.4457869 | Q6: =IF(P6 > 5, "Premium Health", IF(P6 > 3, "Balanced", "High-Risk")) -> Balanced
A7: Regular Menu | B7: Veg Maharaja Mac | C7: =(O7-$K$147)/($K$150) -> 2.466723 | D7: 306 | E7: 832.67 | F7: 24.17 | G7: =Table2[[#This Row],[Protein (g)]]/Table2[[#This Row],[Per Serve Size]] -> 0.078986928 | H7: 37.94 | I7: 16.83 | J7: 0.28 | K7: 36.19 | L7: 93.84 | M7: 11.52 | N7: 6.92 | O7: 1529.22 | P7: =(Table2[[#This Row],[Protein (g)]]/Table2[[#This Row],[Energy (kCal)]])*100-(Table2[[#This Row],[Sodium (mg)]]/1000) -> 1.3734906 | Q7: =IF(P7 > 5, "Premium Health", IF(P7 > 3, "Balanced", "High-Risk")) -> High-Risk
A8: Gourmet Menu | B8: McSpicy Premium Veg Burger | C8: =(O8-$K$147)/($K$150) -> 2.2926806 | D8: 212.5 | E8: 634.71 | F8: 22.44 | G8: =Table2[[#This Row],[Protein (g)]]/Table2[[#This Row],[Per Serve Size]] -> 0.1056 | H8: 39.21 | I8: 20.46 | J8: 0.2 | K8: 43.68 | L8: 46 | M8: 7.57 | N8: 3.28 | O8: 1446.87 | P8: =(Table2[[#This Row],[Protein (g)]]/Table2[[#This Row],[Energy (kCal)]])*100-(Table2[[#This Row],[Sodium (mg)]]/1000) -> 2.0886029 | Q8: =IF(P8 > 5, "Premium Health", IF(P8 > 3, "Balanced", "High-Risk")) -> High-Risk
A9: Gourmet Menu | B9: American Triple Cheese Chicken | C9: =(O9-$K$147)/($K$150) -> 2.1855288 | D9: 195 | E9: 457.94 | F9: 24.43 | G9: =Table2[[#This Row],[Protein (g)]]/Table2[[#This Row],[Per Serve Size]] -> 0.12528205 | H9: 22.65 | I9: 11.56 | J9: 0.17 | K9: 71.23 | L9: 37.45 | M9: 7.64 | N9: 3.84 | O9: 1396.17 | P9: =(Table2[[#This Row],[Protein (g)]]/Table2[[#This Row],[Energy (kCal)]])*100-(Table2[[#This Row],[Sodium (mg)]]/1000) -> 3.93859 | Q9: =IF(P9 > 5, "Premium Health", IF(P9 > 3, "Balanced", "High-Risk")) -> Balanced
A10: Regular Menu | B10: 5 piece Chicken Strips | C10: =(O10-$K$147)/($K$150) -> 1.7562452 | D10: 145 | E10: 411.09 | F10: 25.43 | G10: =Table2[[#This Row],[Protein (g)]]/Table2[[#This Row],[Per Serve Size]] -> 0.17537931 | H10: 28.54 | I10: 0.15 | J10: 75.26 | K10: 6.7 | L10: 0.73 | M10: 0.72 | N10: 0 | O10: 1193.05 | P10: =(Table2[[#This Row],[Protein (g)]]/Table2[[#This Row],[Energy (kCal)]])*100-(Table2[[#This Row],[Sodium (mg)]]/1000) -> 4.9929433 | Q10: =IF(P10 > 5, "Premium Health", IF(P10 > 3, "Balanced", "High-Risk")) -> Balanced
A11: Gourmet Menu | B11: American Triple Cheese Veg | C11: =(O11-$K$147)/($K$150) -> 1.7165547 | D11: 207 | E11: 524.69 | F11: 19.54 | G11: =Table2[[#This Row],[Protein (g)]]/Table2[[#This Row],[Per Serve Size]] -> 0.094396135 | H11: 23.16 | I11: 14.78 | J11: 0.19 | K11: 48.74 | L11: 56.24 | M11: 7.9 | N11: 3.84 | O11: 1174.27 | P11: =(Table2[[#This Row],[Protein (g)]]/Table2[[#This Row],[Energy (kCal)]])*100-(Table2[[#This Row],[Sodium (mg)]]/1000) -> 2.5498338 | Q11: =IF(P11 > 5, "Premium Health", IF(P11 > 3, "Balanced", "High-Risk")) -> High-Risk
A12: Gourmet Menu | B12: Piri piri Mc Spicy Veg Burger | C12: =(O12-$K$147)/($K$150) -> 1.7094112 | D12: 211 | E12: 517.98 | F12: 11.97 | G12: =Table2[[#This Row],[Protein (g)]]/Table2[[#This Row],[Per Serve Size]] -> 0.056729858 | H12: 24.53 | I12: 6.01 | J12: 0.18 | K12: 8.1 | L12: 58.87 | M12: 12.87 | N12: 6.67 | O12: 1170.89 | P12: =(Table2[[#This Row],[Protein (g)]]/Table2[[#This Row],[Energy (kCal)]])*100-(Table2[[#This Row],[Sodium (mg)]]/1000) -> 1.14001 | Q12: =IF(P12 > 5, "Premium Health", IF(P12 > 3, "Balanced", "High-Risk")) -> High-Risk
A13: Gourmet Menu | B13: Cheese Lava Burger | C13: =(O13-$K$147)/($K$150) -> 1.673694 | D13: 240 | E13: 671.06 | F13: 14.99 | G13: =Table2[[#This Row],[Protein (g)]]/Table2[[#This Row],[Per Serve Size]] -> 0.062458333 | H13: 33.48 | I13: 14.12 | J13: 0.21 | K13: 33.21 | L13: 74.25 | M13: 16.27 | N13: 10.01 | O13: 1153.99 | P13: =(Table2[[#This Row],[Protein (g)]]/Table2[[#This Row],[Energy (kCal)]])*100-(Table2[[#This Row],[Sodium (mg)]]/1000) -> 1.0797894 | Q13: =IF(P13 > 5, "Premium Health", IF(P13 > 3, "Balanced", "High-Risk")) -> High-Risk
... A140: Condiments Menu | B140: Sweet Corn | C140: =(O140-$K$147)/($K$150) -> -0.76511913 | D140: 40 | E140: 45.08 | F140: 1.47 | G140: =Table2[[#This Row],[Protein (g)]]/Table2[[#This Row],[Per Serve Size]] -> 0.03675 | H140: 1 | I140: 0.22 | J140: 0.04 | K140: 2 | L140: 7.55 | M140: 2.54 | N140: 0 | O140: 0.04 | P140: =(Table2[[#This Row],[Protein (g)]]/Table2[[#This Row],[Energy (kCal)]])*100-(Table2[[#This Row],[Sodium (mg)]]/1000) -> 3.2608296 | Q140: =IF(P140 > 5, "Premium Health", IF(P140 > 3, "Balanced", "High-Risk")) -> Balanced
A141: Gourmet Menu | B141: Piri piri Mc Spicy Chicken Burger | C141: =(O141-$K$147)/($K$150) -> -0.76520367 | D141: 228 | E141: 443.4 | F141: 25.63 | G141: =Table2[[#This Row],[Protein (g)]]/Table2[[#This Row],[Per Serve Size]] -> 0.11241228 | H141: 17.3 | I141: 4.01 | J141: 0.19 | K141: 64.19 | L141: 43.29 | M141: 9.29 | N141: 6.32 | P141: =(Table2[[#This Row],[Protein (g)]]/Table2[[#This Row],[Energy (kCal)]])*100-(Table2[[#This Row],[Sodium (mg)]]/1000) -> 5.7803338 | Q141: =IF(P141 > 5, "Premium Health", IF(P141 > 3, "Balanced", "High-Risk")) -> Premium Health
A142: Regular Menu | B142: L1 Coffee | C142: =(O142-$K$147)/($K$150) -> -0.76520367 | D142: 200 | E142: 6.8 | F142: 0 | G142: =Table2[[#This Row],[Protein (g)]]/Table2[[#This Row],[Per Serve Size]] -> 0 | H142: 0 | I142: 0 | J142: 0 | K142: 0 | L142: 1.7 | M142: 0 | N142: 0 | O142: 0 | P142: =(Table2[[#This Row],[Protein (g)]]/Table2[[#This Row],[Energy (kCal)]])*100-(Table2[[#This Row],[Sodium (mg)]]/1000) -> 0 | Q142: =IF(P142 > 5, "Premium Health", IF(P142 > 3, "Balanced", "High-Risk")) -> High-Risk
H146: Statistic | I146: Energy (kCal) | J146: Protein (g) | K146: Sodium (mg)
H147: Mean | I147: 244.63546 | J147: 7.4935461 | K147: 362.06414
H148: Standard Error | I148: 15.626536 | J148: 0.70209053 | K148: 39.98936
H149: Median | I149: 219.36 | J149: 4.79 | K149: 152.025
H150: Standard Deviation | I150: 185.55484 | J150: 8.3368631 | K150: 473.16049
H151: Range | I151: 834.36 | J151: 39.47 | K151: 2399.49
H152: Minimum | I152: 0 | J152: 0 | K152: 0
H153: Maximum | I153: 834.36 | J153: 39.47 | K153: 2399.49
H154: Count | I154: 141 | J154: 141 | K154: 140
H156: Correlation of serving size and protein | I156: =CORREL(D:D,F:F) -> -0.090593339

Sheet Correlation sheet
B4: Energy | C4: Protein | D4: Sodium | E4: Total Fat | F4: Per Serve Size | G4: Total Sugars (g)
A5: Energy | B5: =CORREL(Table2[Energy (kCal)],Table2[Energy (kCal)]) -> 1 | C5: =CORREL(Table2[Energy (kCal)],Table2[Protein (g)]) -> 0.82683309 | D5: =CORREL(Table2[Energy (kCal)],Table2[Sodium (mg)]) -> 0.85473048 | E5: =CORREL(Table2[Energy (kCal)],Table2[Total fat (g)]) -> 0.90864202 | F5: =CORREL(Table2[Energy (kCal)],Table2[Per Serve Size]) -> 0.0020985989 | G5: =CORREL(Table2[Energy (kCal)],Table2[Total Sugars (g)]) -> 0.063306454
A6: Protein | B6: =CORREL(Table2[Protein (g)],Table2[Energy (kCal)]) -> 0.82683309 | C6: =CORREL(Table2[Protein (g)],Table2[Protein (g)]) -> 1 | D6: =CORREL(Table2[Protein (g)],Table2[Sodium (mg)]) -> 0.91499267 | E6: =CORREL(Table2[Protein (g)],Table2[Total fat (g)]) -> 0.87559381 | F6: =CORREL(Table2[Protein (g)],Table2[Per Serve Size]) -> -0.090593339 | G6: =CORREL(Table2[Protein (g)],Table2[Total Sugars (g)]) -> -0.28287549
A7: Sodium | B7: =CORREL(Table2[Sodium (mg)],Table2[Energy (kCal)]) -> 0.85473048 | C7: =CORREL(Table2[Sodium (mg)],Table2[Protein (g)]) -> 0.91499267 | D7: =CORREL(Table2[Sodium (mg)],Table2[Sodium (mg)]) -> 1 | E7: =CORREL(Table2[Sodium (mg)],Table2[Total fat (g)]) -> 0.87491072 | F7: =CORREL(Table2[Sodium (mg)],Table2[Per Serve Size]) -> -0.11777512 | G7: =CORREL(Table2[Sodium (mg)],Table2[Total Sugars (g)]) -> -0.29917145
A8: Total Fat | B8: =CORREL(Table2[Total fat (g)],Table2[Energy (kCal)]) -> 0.90864202 | C8: =CORREL(Table2[Total fat (g)],Table2[Protein (g)]) -> 0.87559381 | D8: =CORREL(Table2[Total fat (g)],Table2[Sodium (mg)]) -> 0.87491072 | E8: =CORREL(Table2[Total fat (g)],Table2[Total fat (g)]) -> 1 | F8: =CORREL(Table2[Total fat (g)],Table2[Per Serve Size]) -> -0.14303007 | G8: =CORREL(Table2[Total fat (g)],Table2[Total Sugars (g)]) -> -0.22012502
A9: Per Serve Size | B9: =CORREL(Table2[Per Serve Size],Table2[Energy (kCal)]) -> 0.0020985989 | C9: =CORREL(Table2[Per Serve Size],Table2[Protein (g)]) -> -0.090593339 | D9: =CORREL(Table2[Per Serve Size],Table2[Sodium (mg)]) -> -0.11777512 | E9: =CORREL(Table2[Per Serve Size],Table2[Total fat (g)]) -> -0.14303007 | F9: =CORREL(Table2[Per Serve Size],Table2[Per Serve Size]) -> 1 | G9: =CORREL(Table2[Per Serve Size],Table2[Total Sugars (g)]) -> 0.46858065
A10: Total Sugars (g) | B10: =CORREL(Table2[Total Sugars (g)],Table2[Energy (kCal)]) -> 0.063306454 | C10: =CORREL(Table2[Total Sugars (g)],Table2[Protein (g)]) -> -0.28287549 | D10: =CORREL(Table2[Total Sugars (g)],Table2[Sodium (mg)]) -> -0.29917145 | E10: =CORREL(Table2[Total Sugars (g)],Table2[Total fat (g)]) -> -0.22012502 | F10: =CORREL(Table2[Total Sugars (g)],Table2[Per Serve Size]) -> 0.46858065 | G10: =CORREL(Table2[Total Sugars (g)],Table2[Total Sugars (g)]) -> 1
B12: 1 | C12: 0.5 | D12: 0 | E12: -0.5 | F12: -1
B13: Strong Positive | C13: Weak Positive | D13: No Linear Relationship | E13: Weak Negative | F13: Strong Negative

Sheet Mnue Vs avg Protein 
A3: Menu Category | B3: Average of Protein (g)
A4: Beverages Menu | B4: 0.26823529
A5: Breakfast Menu | B5: 7.6366667
A6: Condiments Menu | B6: 0.73111111
A7: Desserts Menu | B7: 2.815
A8: Gourmet Menu | B8: 21.684545
A9: McCafe Menu | B9: 4.2954902
A10: Regular Menu | B10: 12.990833
A11: Grand Total | B11: 7.4935461

Sheet Bundle Data_set
A1: Mains | G1: Sides
A2: Menu Category | B2: Menu Items | C2: Energy (kCal) | D2: Protein (g) | G2: Menu Category | H2: Menu Items | I2: Energy (kCal) | J2: Protein (g)
A3: Regular Menu | B3: McVeggieâ„¢ Burger | C3: 402.05 | D3: 10.24 | G3: Breakfast Menu | H3: Hash Brown | I3: 140.29 | J3: 1.93
A4: Regular Menu | B4: McAloo Tikki BurgerÂ® | C4: 339.52 | D4: 8.5 | G4: Breakfast Menu | H4: Espresso | I4: 12.87 | J4: 0.52
G5: Breakfast Menu | H5: Espresso Machiato | I5: 44.98 | J5: 2.09
G6: Breakfast Menu | H6: Americano (S) | I6: 12.87 | J6: 0.52
A7: Regular Menu | B7: American Veg Burger | C7: 512.17 | D7: 15.3 | G7: Breakfast Menu | H7: Americano (R) | I7: 23.07 | J7: 0.94
G8: Breakfast Menu | H8: Americano (L) | I8: 26.71 | J8: 1.09
A9: Regular Menu | B9: Green Chilli Aloo Naan | C9: 356.09 | D9: 7.91 | G9: Breakfast Menu | H9: Cappuccino (S) | I9: 125.25 | J9: 6.02
A10: Regular Menu | B10: Pizza Puff | C10: 228.21 | D10: 5.45 | G10: Breakfast Menu | H10: Cappuccino (R) | I10: 183.61 | J10: 8.79
A11: Regular Menu | B11: Mc chicken Burger | C11: 400.8 | D11: 15.66 | G11: McCafe Menu | H11: Cappuccino (L) | I11: 219.36 | J11: 10.51
A12: Regular Menu | B12: FILLET-O-FISH Burger | C12: 348.11 | D12: 15.44 | G12: McCafe Menu | H12: Latte (S) | I12: 147.72 | J12: 7.12
A13: Regular Menu | B13: Mc Spicy Chicken Burger | C13: 451.92 | D13: 21.46 | G13: McCafe Menu | H13: Latte (R) | I13: 190.03 | J13: 9.1
A14: Regular Menu | B14: Spicy Chicken Wrap | C14: 567.19 | D14: 23.74 | G14: McCafe Menu | H14: Latte (L) | I14: 232.2 | J14: 11.14
G15: McCafe Menu | H15: Flat White (S) | I15: 166.99 | J15: 8.06
A16: Regular Menu | B16: American Chicken Burger | C16: 446.95 | D16: 20.29 | G16: McCafe Menu | H16: Flat White (R) | I16: 215.72 | J16: 10.36
A17: Regular Menu | B17: Chicken Kebab Burger | C17: 357.05 | D17: 8.64 | G17: McCafe Menu | H17: Flat White (L) | I17: 251.47 | J17: 12.08
A18: Regular Menu | B18: Green Chilli Kebab naan | C18: 230.95 | D18: 5.67 | G18: McCafe Menu | H18: Mocha (S) | I18: 185.85 | J18: 7.15
A19: Regular Menu | B19: Mc Egg Masala Burger | C19: 290.42 | D19: 12.45 | G19: McCafe Menu | H19: Mocha (R) | I19: 244 | J19: 8.99
A20: Regular Menu | B20: Mc Egg Burger for Happy Meal | C20: 282.98 | D20: 12.29 | G20: McCafe Menu | H20: Mocha (L) | I20: 302.02 | J20: 10.88
A21: Regular Menu | B21: Ghee Rice with Mc Spicy Fried Chicken 1 pc | C21: 720.3 | D21: 26.91 | G21: McCafe Menu | H21: Babycino | I21: 143.5 | J21: 3.87
A22: Regular Menu | B22: McSpicy Fried Chicken 1 pc | C22: 248.76 | D22: 17.33 | G22: McCafe Menu | H22: Hot Chocolate (S) | I22: 239.42 | J22: 6.73
A23: Regular Menu | B23: 4 piece Chicken McNuggets | C23: 169.68 | D23: 10.03 | G23: McCafe Menu | H23: Hot Chocolate (R) | I23: 296.81 | J23: 7.7
A24: Regular Menu | B24: 6 piece Chicken McNuggets | C24: 254.52 | D24: 15.04 | G24: McCafe Menu | H24: Hot Chocolate (L) | I24: 383.29 | J24: 11.01
A25: Regular Menu | B25: 9 piece Chicken McNuggets | C25: 381.77 | D25: 22.56 | G25: McCafe Menu | H25: Premium Dark Hot Chocolate | I25: 214.21 | J25: 6.15
A26: Regular Menu | B26: 2 piece Chicken Strips | C26: 164.44 | D26: 10.17 | G26: McCafe Menu | H26: Double Dark Hot Chocolate | I26: 255.78 | J26: 6.87
A27: Regular Menu | B27: 3 piece Chicken Strips | C27: 246.65 | D27: 15.26 | G27: McCafe Menu | H27: English Breakfast (S) | I27: 9.93 | J27: 0.56
... A36: Gourmet Menu | B36: American Triple Cheese Veg | C36: 524.69 | D36: 19.54 | G36: McCafe Menu | H36: Lemon Ice Tea | I36: 121.86 | J36: 0.27
G37: McCafe Menu | H37: Strawberry Ice Tea | I37: 94.95 | J37: 0.24
G38: McCafe Menu | H38: Green Apple Ice Tea | I38: 94.94 | J38: 0.24
G39: McCafe Menu | H39: Iced Coffee | I39: 185.34 | J39: 4.36
G40: McCafe Menu | H40: Cold Coffee Frappe | I40: 331.17 | J40: 4.98
G41: McCafe Menu | H41: Mocha Frappe | I41: 397.98 | J41: 5.49
A42: Gourmet Menu | B42: Piri piri Mc Spicy Chicken Burger | C42: 443.4 | D42: 25.63 | G42: McCafe Menu | H42: Chocolate Oreo Frappe | I42: 481.11 | J42: 6.03
A43: Gourmet Menu | B43: Piri piri Mc Spicy Veg Burger | C43: 517.98 | D43: 11.97 | G43: McCafe Menu | H43: Strawberry Shake | I43: 255.51 | J43: 3.67
A44: Gourmet Menu | B44: Cheesy Veg Nuggets (6pc) | C44: 252.29 | D44: 8.48 | G44: McCafe Menu | H44: Chocolate Shake | I44: 270.9 | J44: 4.16
A45: Gourmet Menu | B45: Cheesy Veg Nuggets (9pc) | C45: 378.43 | D45: 12.72 | G45: McCafe Menu | H45: Mango Smoothie | I45: 231.44 | J45: 3.21
G46: McCafe Menu | H46: Mixed Berry Smoothie | I46: 235.43 | J46: 3.33
G47: McCafe Menu | H47: Raw Mango Cooler | I47: 102.38 | J47: 0.14
G48: McCafe Menu | H48: Mix Berry Cooler | I48: 103.85 | J48: 0.16
...

Sheet Bundle_sheet
A1: Bundle ID | B1: Main Item | C1: Side | D1: Main Energy | E1: Side Energy | F1: Total Bundle Energy | G1: Main Protein | H1: Side Protein | I1: Total Protein | J1: Healthy Combo
A2: Make Your Own Bundle | B2: Green Chilli Aloo Naan | C2: Espresso Machiato | D2: =VLOOKUP(B2,Table3[[Menu Items]:[Energy (kCal)]],2,FALSE) -> 356.09 | E2: =VLOOKUP(C2,Table4[[Menu Items]:[Energy (kCal)]],2,FALSE) -> 44.98 | F2: =D2+E2 -> 401.07 | G2: =VLOOKUP(Bundle_sheet!B2,Table3[[Menu Items]:[Protein (g)]],3,FALSE) -> 7.91 | H2: =VLOOKUP(C2,Table4[[Menu Items]:[Protein (g)]],3,FALSE) -> 2.09 | I2: =G2+H2 -> 10 | J2: =IF(AND(F2<500, I2>=12), "Nutri-Bundle", "Standard") -> Standard
A3: BD-001 | B3: FILLET-O-FISH Burger | C3: Coke Zero Can | D3: 348 | E3: 0.99 | F3: =D3+E3 -> 348.99 | G3: 15.44 | H3: 0 | I3: =G3+H3 -> 15.44 | J3: =IF(AND(F3<500, I3>=12), "Nutri-Bundle", "Standard") -> Nutri-Bundle
A4: BD-002 | B4: Mc chicken Burger | C4: Black Coffee | D4: 400.8 | E4: 5 | F4: =D4+E4 -> 405.8 | G4: 15.66 | H4: 0 | I4: =G4+H4 -> 15.66 | J4: =IF(AND(F4<500, I4>=12), "Nutri-Bundle", "Standard") -> Nutri-Bundle
A5: BD-003 | B5: Egg McMuffin | C5: Americano (S) | D5: 283 | E5: 12 | F5: =D5+E5 -> 295 | G5: 13.5 | H5: 0 | I5: =G5+H5 -> 13.5 | J5: =IF(AND(F5<500, I5>=12), "Nutri-Bundle", "Standard") -> Nutri-Bundle
A6: BD-004 | B6: Chicken Strips (3pc) | C6: Small Coca-Cola | D6: 246 | E6: 109 | F6: =D6+E6 -> 355 | G6: 15.5 | H6: 0 | I6: =G6+H6 -> 15.5 | J6: =IF(AND(F6<500, I6>=12), "Nutri-Bundle", "Standard") -> Nutri-Bundle
A7: BD-005 | B7: 6pc Chicken McNuggets | C7: Regular Wedges | D7: 254 | E7: 204 | F7: =D7+E7 -> 458 | G7: 13.5 | H7: 3 | I7: =G7+H7 -> 16.5 | J7: =IF(AND(F7<500, I7>=12), "Nutri-Bundle", "Standard") -> Nutri-Bundle

Sheet Scatter Chart 

Sheet Descriptive Statistics
E3: Statistic | F3: Energy (kCal) | G3: Protein (g) | H3: Sodium (mg)
E4: Mean | F4: =AVERAGE('Data_set '!E2:E142) -> 244.63546 | G4: =AVERAGE('Data_set '!F2:F142) -> 7.4935461 | H4: =AVERAGE('Data_set '!O2:O142) -> 362.06414
E5: Standard Error | F5: =(_xlfn.STDEV.S('Data_set '!E2:E142))/(SQRT(COUNT('Data_set '!E2:E142))) -> 15.626536 | G5: =(_xlfn.STDEV.S('Data_set '!F2:F142))/(SQRT(COUNT('Data_set '!F2:F142))) -> 0.70209053 | H5: =(_xlfn.STDEV.S('Data_set '!O2:O142))/(SQRT(COUNT('Data_set '!O2:O142))) -> 39.98936
E6: Median | F6: =MEDIAN('Data_set '!E2:E142) -> 219.36 | G6: =MEDIAN('Data_set '!F2:F142) -> 4.79 | H6: =MEDIAN('Data_set '!O2:O142) -> 152.025
E7: Standard Deviation | F7: =_xlfn.STDEV.S('Data_set '!E2:E142) -> 185.55484 | G7: =_xlfn.STDEV.S('Data_set '!F2:F142) -> 8.3368631 | H7: =_xlfn.STDEV.S('Data_set '!O2:O142) -> 473.16049
E8: Range | F8: =F10-F9 -> 834.36 | G8: =G10-G9 -> 39.47 | H8: =H10-H9 -> 2399.49
E9: Minimum | F9: =MIN('Data_set '!E2:E142) -> 0 | G9: =MIN('Data_set '!F2:F142) -> 0 | H9: =MIN('Data_set '!O2:O142) -> 0
E10: Maximum | F10: =MAX('Data_set '!E2:E142) -> 834.36 | G10: =MAX('Data_set '!F2:F142) -> 39.47 | H10: =MAX('Data_set '!O2:O142) -> 2399.49
E11: Count | F11: =COUNT('Data_set '!E2:E142) -> 141 | G11: =COUNT('Data_set '!F2:F142) -> 141 | H11: =COUNT('Data_set '!O2:O142) -> 140

Sheet Sheet1
A3: Strategic Health Tier | B3: Count of Strategic Health Tier
A4: Balanced | B4: 32
A5: High-Risk | B5: 89
A6: Premium Health | B6: 19
A7: Grand Total | B7: 140

Sheet Sheet2
A3: Menu Category | B3: Average of Protein-to-Weight Ratio
A4: Beverages Menu | B4: 0.00093530212
A5: Breakfast Menu | B5: 0.059506957
A6: Condiments Menu | B6: 0.045014727
A7: Desserts Menu | B7: 0.023955591
A8: Gourmet Menu | B8: 0.098605508
A9: McCafe Menu | B9: 0.017992889
A10: Regular Menu | B10: 0.08710667
A11: Grand Total | B11: 0.046097065
C14: Menu Items | D14: Sodium_Z-Score
C15: Ghee Rice with Mc Spicy Fried Chicken 1 pc | D15: 4.3059932
C16: Chunky Chipotle American Burger Chicken | D16: 3.2635985
C17: Chicken Maharaja Mac | D17: 3.1546291
C18: Chicken Cheese Lava Burger | D18: 2.9228473
C19: McSpicy Premium Chicken Burger | D19: 2.6477609
C20: Veg Maharaja Mac | D20: 2.466723
C21: McSpicy Premium Veg Burger | D21: 2.2926806
C22: American Triple Cheese Chicken | D22: 2.1855288
C23: 5 piece Chicken Strips | D23: 1.7562452
C24: American Triple Cheese Veg | D24: 1.7165547
C25: Piri piri Mc Spicy Veg Burger | D25: 1.7094112
C26: Cheese Lava Burger | D26: 1.673694
... C156: Grand Total | D156: -0.76520367
